Workbook

Sheet Budget 26-27
C3: =TODAY() -> 46252 | D3: BUDGET
C5: Income | E5: Gross | F5: Net | I5: 46204 | J5: 46235 | K5: 46295 | L5: =EDATE(K5,1) -> 46325 | M5: =EDATE(L5,1) -> 46356 | N5: =EDATE(M5,1) -> 46386 | O5: =EDATE(N5,1) -> 46417 | P5: =EDATE(O5,1) -> 46446 | Q5: =EDATE(P5,1) -> 46474 | R5: =EDATE(Q5,1) -> 46505 | S5: =EDATE(R5,1) -> 46535 | ... U5: =EDATE(T5,1) -> 46596
C6: Base Salary | E6: 122500 | F6: =E6-F7 -> 88004 | H6: Income
C7: Tax Rate (State, Federal, City, Medicare, Social Security) | D7: 0.2816 | F7: =D7*E6 -> 34496 | H7: Net Base Salary | I7: 0 | J7: =$F$8 -> 7333.6667 | K7: =$F$8 -> 7333.6667 | L7: =$F$8 -> 7333.6667 | M7: =$F$8 -> 7333.6667 | N7: =$F$8 -> 7333.6667 | O7: =$F$8 -> 7333.6667 | P7: =$F$8 -> 7333.6667 | Q7: =$F$8 -> 7333.6667 | ... U7: =$F$8 -> 7333.6667
C8: Per Month | E8: =E6/12 -> 10208.333 | F8: =F6/12 -> 7333.6667 | H8: Net Bonus | I8: 0 | J8: =IF(J$5=$F$12, $F$10, 0) -> 7000 | K8: =IF(K$5=$F$12, $F$10, 0) -> 0 | L8: =IF(L$5=$F$12, $F$10, 0) -> 0 | M8: =IF(M$5=$F$12, $F$10, 0) -> 0 | N8: =IF(N$5=$F$12, $F$10, 0) -> 0 | O8: =IF(O$5=$F$12, $F$10, 0) -> 0 | P8: =IF(P$5=$F$12, $F$10, 0) -> 0 | Q8: =IF(Q$5=$F$12, $F$10, 0) -> 0 | ... U8: =IF(U$5=$F$12, $F$10, 0) -> 0
C9: Max Rent Pmt. | D9: 0.3 | E9: =E8*D9 -> 3062.5 | F9: =F8*D9 -> 2200.1 | H9: Investment | I9: 0 | J9: =I21*($F$15/12) -> 0 | K9: =J21*($F$15/12) -> 0 | L9: =K21*($F$15/12) -> 0 | M9: =L21*($F$15/12) -> 0 | N9: =M21*($F$15/12) -> 0 | O9: =N21*($F$15/12) -> 0 | P9: =O21*($F$15/12) -> 0 | Q9: =P21*($F$15/12) -> 0 | ... U9: =T21*($F$15/12) -> 0
C10: Bonus Amount | E10: 10000 | F10: =E10-F11 -> 7000 | H10: Tax Refund
C11: Tax Rate (State, Federal, City, Medicare, Social Security) | D11: 0.3 | F11: =D11*E10 -> 3000 | H11: Total Income | I11: =SUM(I7:I10) -> 0 | J11: =SUM(J7:J10) -> 14333.667 | K11: =SUM(K7:K10) -> 7333.6667 | L11: =SUM(L7:L10) -> 7333.6667 | M11: =SUM(M7:M10) -> 7333.6667 | N11: =SUM(N7:N10) -> 7333.6667 | O11: =SUM(O7:O10) -> 7333.6667 | P11: =SUM(P7:P10) -> 7333.6667 | ... U11: =SUM(U7:U10) -> 7333.6667
C12: Bonus Payout Date | F12: 46235
C13: Total Salary | E13: =E6+E10 -> 132500 | F13: =F6+F10 -> 95004 | H13: Expense
C14: Total Tax | F14: =F11+F7 -> 37496 | H14: Rent | I14: =$F$31 -> 8000 | J14: 1297.85 | K14: =$F$36 -> 2435 | L14: =$F$36 -> 2435 | M14: =$F$36 -> 2435 | N14: =$F$36 -> 2435 | O14: =$F$36 -> 2435 | P14: =$F$36 -> 2435 | Q14: =$F$36 -> 2435 | R14: =$F$36 -> 2435 | ... U14: =$F$36 -> 2435
C15: High Yield Savings APR | F15: 0 | H15: Budgeted Expenses | J15: =$E$23 -> 1364.0633 | K15: =$E$23 -> 1364.0633 | L15: =$E$23 -> 1364.0633 | M15: =$E$23 -> 1364.0633 | N15: =$E$23 -> 1364.0633 | O15: =$E$23 -> 1364.0633 | P15: =$E$23 -> 1364.0633 | Q15: =$E$23 -> 1364.0633 | ... U15: =$E$23 -> 1364.0633
H16: Discretionary | J16: =$E$25 -> 750 | K16: =$E$25 -> 750 | L16: =$E$25 -> 750 | M16: =$E$25 -> 750 | N16: =$E$25 -> 750 | O16: =$E$25 -> 750 | P16: =$E$25 -> 750 | Q16: =$E$25 -> 750 | ... U16: =$E$25 -> 750
C17: Expenses | E17: Per Month | F17: Per Week | H17: Total Expenses | J17: =SUM(J14:J16) -> 3411.9133 | K17: =SUM(K14:K16) -> 4549.0633 | L17: =SUM(L14:L16) -> 4549.0633 | M17: =SUM(M14:M16) -> 4549.0633 | N17: =SUM(N14:N16) -> 4549.0633 | O17: =SUM(O14:O16) -> 4549.0633 | P17: =SUM(P14:P16) -> 4549.0633 | Q17: =SUM(Q14:Q16) -> 4549.0633 | ... U17: =SUM(U14:U16) -> 4549.0633
C18: LIRR/Subway | E18: 60 | F18: =E18/4 -> 15
C19: Lunch in Office | D19: 3 | E19: =F19*4 -> 168 | F19: =14*D19 -> 42 | H19: Net Income | J19: =SUM(J11,-J17) -> 10921.753 | K19: =SUM(K11,-K17) -> 2784.6033 | L19: =SUM(L11,-L17) -> 2784.6033 | M19: =SUM(M11,-M17) -> 2784.6033 | N19: =SUM(N11,-N17) -> 2784.6033 | O19: =SUM(O11,-O17) -> 2784.6033 | P19: =SUM(P11,-P17) -> 2784.6033 | Q19: =SUM(Q11,-Q17) -> 2784.6033 | ... U19: =SUM(U11,-U17) -> 2784.6033
C20: Sunday Grocery | E20: =F20*4 -> 600 | F20: 150
C21: Jordan Travel | E21: =500 -> 500 | F21: =E21 / 4 -> 125 | H21: Savings Balance | J21: =SUM($J$19:J19) -> 10921.753 | K21: =SUM($J$19:K19) -> 13706.357 | L21: =SUM($J$19:L19) -> 16490.96 | M21: =SUM($J$19:M19) -> 19275.563 | N21: =SUM($J$19:N19) -> 22060.167 | O21: =SUM($J$19:O19) -> 24844.77 | P21: =SUM($J$19:P19) -> 27629.373 | Q21: =SUM($J$19:Q19) -> 30413.977 | ... U21: =SUM($J$19:U19) -> 41552.39
C22: Subscriptions | E22: =I37 -> 36.063333 | F22: =E22/4 -> 9.0158333
C23: Total Fixed | E23: =SUM(E18:E22) -> 1364.0633 | F23: =E23/4 -> 341.01583 | H23: LIRR Ticket Calc | J23: Per Month | K23: Per Week | M23: Controllable | O23: Per Month | P23: Per Week
H24: Trips | J24: =K24*4 -> 32 | K24: 8 | M24: Jordan Travel | O24: =E21 -> 500 | P24: =F21 -> 125
C25: Discretionary Expenses | E25: 750 | F25: =E25/4 -> 187.5 | M25: Food | O25: =E19+E20 -> 768 | P25: =F19+F20 -> 192
H26: One Way Peak | I26: 17.5 | J26: =I26*J24 -> 560 | K26: =I26*K24 -> 140 | M26: Misc. | O26: =E25 -> 750 | P26: =F25 -> 187.5
C27: Total Expenses | E27: =SUM(E23,E25) -> 2114.0633 | F27: =SUM(F23,F25) -> 528.51583 | H27: Monthly | J27: 341 | K27: =J27/4 -> 85.25 | M27: Total | O27: =SUM(O24:O26) -> 2018 | P27: =SUM(P24:P26) -> 504.5
K28: =K27/K24 -> 10.65625
C30: Rent | E30: Total | F30: Per Person | H30: Subscriptions | I30: Per Month
C31: First Month Cost: | E31: 24000 | F31: =E31/3 -> 8000 | H31: Apple Music | I31: 5.99
C32: Base Rent: | E32: 6950 | F32: =E32/3 -> 2316.6667 | H32: ICloud+ | I32: 2.99
C33: ~Utilities: | E33: 355 | F33: =E33/3 -> 118.33333 | H33: AMEX Gold | I33: =325/12 -> 27.083333
C36: Total Rent Monthly - First Month: | E36: =SUM(E32:E35) -> 7305 | F36: =E36 / 3 -> 2435
C37: Total Rent Yearly: | E37: =(E36*11)+E31 -> 104355 | F37: =E37/3 -> 34785 | H37: Total: | I37: =SUM(I31:I36) -> 36.063333
C40: Summary of Savings | D40: Per Person
C41: Total Savings | D41: =U21 -> 41552.39
C42: % Of Salary Saved | D42: =U21/F13 -> 0.43737516

Sheet Actual 26-27
C3: =TODAY() -> 46252 | D3: BUDGET
C5: Income | E5: Gross | F5: Net | I5: 46204 | J5: 46235 | K5: 46295 | L5: =EDATE(K5,1) -> 46325 | M5: =EDATE(L5,1) -> 46356 | N5: =EDATE(M5,1) -> 46386 | O5: =EDATE(N5,1) -> 46417 | P5: =EDATE(O5,1) -> 46446 | Q5: =EDATE(P5,1) -> 46474 | R5: =EDATE(Q5,1) -> 46505 | S5: =EDATE(R5,1) -> 46535 | ... U5: =EDATE(T5,1) -> 46596
C6: ='Budget 26-27'!C6 -> Base Salary | E6: ='Budget 26-27'!E6 -> 122500 | F6: ='Budget 26-27'!F6 -> 88004 | H6: Income
C7: ='Budget 26-27'!C7 -> Tax Rate (State, Federal, City, Medicare, Social Security) | D7: ='Budget 26-27'!D7 -> 0.2816 | F7: ='Budget 26-27'!F7 -> 34496 | H7: Net Base Salary | I7: ='Budget 26-27'!I7 -> 0 | J7: ='Budget 26-27'!J7 -> 7333.6667 | K7: ='Budget 26-27'!K7 -> 7333.6667 | L7: ='Budget 26-27'!L7 -> 7333.6667 | M7: ='Budget 26-27'!M7 -> 7333.6667 | N7: ='Budget 26-27'!N7 -> 7333.6667 | O7: ='Budget 26-27'!O7 -> 7333.6667 | P7: ='Budget 26-27'!P7 -> 7333.6667 | ... U7: ='Budget 26-27'!U7 -> 7333.6667
C8: ='Budget 26-27'!C8 -> Per Month | E8: ='Budget 26-27'!E8 -> 10208.333 | F8: ='Budget 26-27'!F8 -> 7333.6667 | H8: Net Bonus | I8: ='Budget 26-27'!I8 -> 0 | J8: ='Budget 26-27'!J8 -> 7000 | K8: ='Budget 26-27'!K8 -> 0 | L8: ='Budget 26-27'!L8 -> 0 | M8: ='Budget 26-27'!M8 -> 0 | N8: ='Budget 26-27'!N8 -> 0 | O8: ='Budget 26-27'!O8 -> 0 | P8: ='Budget 26-27'!P8 -> 0 | ... U8: ='Budget 26-27'!U8 -> 0
C9: ='Budget 26-27'!C9 -> Max Rent Pmt. | D9: ='Budget 26-27'!D9 -> 0.3 | E9: ='Budget 26-27'!E9 -> 3062.5 | F9: ='Budget 26-27'!F9 -> 2200.1 | H9: Investment | J9: ='Budget 26-27'!J9 -> 0 | K9: ='Budget 26-27'!K9 -> 0 | L9: ='Budget 26-27'!L9 -> 0 | M9: ='Budget 26-27'!M9 -> 0 | N9: ='Budget 26-27'!N9 -> 0 | O9: ='Budget 26-27'!O9 -> 0 | P9: ='Budget 26-27'!P9 -> 0 | Q9: ='Budget 26-27'!Q9 -> 0 | ... U9: ='Budget 26-27'!U9 -> 0
C10: ='Budget 26-27'!C10 -> Bonus Amount | E10: ='Budget 26-27'!E10 -> 10000 | F10: ='Budget 26-27'!F10 -> 7000 | H10: Tax Refund | J10: ='Budget 26-27'!J10 -> 0 | K10: ='Budget 26-27'!K10 -> 0 | L10: ='Budget 26-27'!L10 -> 0 | M10: ='Budget 26-27'!M10 -> 0 | N10: ='Budget 26-27'!N10 -> 0 | O10: ='Budget 26-27'!O10 -> 0 | P10: ='Budget 26-27'!P10 -> 0 | Q10: ='Budget 26-27'!Q10 -> 0 | ... U10: ='Budget 26-27'!U10 -> 0
C11: ='Budget 26-27'!C11 -> Tax Rate (State, Federal, City, Medicare, Social Security) | D11: ='Budget 26-27'!D11 -> 0.3 | F11: ='Budget 26-27'!F11 -> 3000 | H11: Total Income | I11: ='Budget 26-27'!I11 -> 0 | J11: ='Budget 26-27'!J11 -> 14333.667 | K11: ='Budget 26-27'!K11 -> 7333.6667 | L11: ='Budget 26-27'!L11 -> 7333.6667 | M11: ='Budget 26-27'!M11 -> 7333.6667 | N11: ='Budget 26-27'!N11 -> 7333.6667 | O11: ='Budget 26-27'!O11 -> 7333.6667 | P11: ='Budget 26-27'!P11 -> 7333.6667 | ... U11: ='Budget 26-27'!U11 -> 7333.6667
C12: ='Budget 26-27'!C12 -> Bonus Payout Date | F12: ='Budget 26-27'!F12 -> 46235 | H12: Budget | I12: ='Budget 26-27'!I11 -> 0 | J12: ='Budget 26-27'!J11 -> 14333.667 | K12: ='Budget 26-27'!K11 -> 7333.6667 | L12: ='Budget 26-27'!L11 -> 7333.6667 | M12: ='Budget 26-27'!M11 -> 7333.6667 | N12: ='Budget 26-27'!N11 -> 7333.6667 | O12: ='Budget 26-27'!O11 -> 7333.6667 | P12: ='Budget 26-27'!P11 -> 7333.6667 | ... U12: ='Budget 26-27'!U11 -> 7333.6667
C13: ='Budget 26-27'!C13 -> Total Salary | E13: ='Budget 26-27'!E13 -> 132500 | F13: ='Budget 26-27'!F13 -> 95004 | H13: % of Budget | I13: =I11/I12 -> #DIV/0! | J13: =J11/J12 -> 1 | K13: =K11/K12 -> 1 | L13: =L11/L12 -> 1 | M13: =M11/M12 -> 1 | N13: =N11/N12 -> 1 | O13: =O11/O12 -> 1 | P13: =P11/P12 -> 1 | ... U13: =U11/U12 -> 1
C14: ='Budget 26-27'!C14 -> Total Tax | F14: ='Budget 26-27'!F14 -> 37496 | H14: $ Over/Under | I14: =I12-I11 -> 0 | J14: =J12-J11 -> 0 | K14: =K12-K11 -> 0 | L14: =L12-L11 -> 0 | M14: =M12-M11 -> 0 | N14: =N12-N11 -> 0 | O14: =O12-O11 -> 0 | P14: =P12-P11 -> 0 | ... U14: =U12-U11 -> 0
C15: ='Budget 26-27'!C15 -> High Yield Savings APR | F15: ='Budget 26-27'!F15 -> 0
H16: Expense
C17: Expenses | E17: Per Month | F17: Per Week | H17: Rent | I17: ='Budget 26-27'!I14 -> 8000 | J17: ='Budget 26-27'!J14 -> 1297.85 | K17: ='Budget 26-27'!K14 -> 2435 | L17: ='Budget 26-27'!L14 -> 2435 | M17: ='Budget 26-27'!M14 -> 2435 | N17: ='Budget 26-27'!N14 -> 2435 | O17: ='Budget 26-27'!O14 -> 2435 | P17: ='Budget 26-27'!P14 -> 2435 | ... U17: ='Budget 26-27'!U14 -> 2435
C18: ='Budget 26-27'!C18 -> LIRR/Subway | E18: ='Budget 26-27'!E18 -> 60 | F18: ='Budget 26-27'!F18 -> 15 | H18: Amex Gold | I18: 2494.31
C19: ='Budget 26-27'!C19 -> Lunch in Office | D19: ='Budget 26-27'!D19 -> 3 | E19: ='Budget 26-27'!E19 -> 168 | F19: ='Budget 26-27'!F19 -> 42 | H19: BOA | I19: 40
C20: ='Budget 26-27'!C20 -> Sunday Grocery | E20: ='Budget 26-27'!E20 -> 600 | F20: ='Budget 26-27'!F20 -> 150 | H20: Utilities
C21: ='Budget 26-27'!C21 -> Jordan Travel | E21: ='Budget 26-27'!E21 -> 500 | F21: ='Budget 26-27'!F21 -> 125 | H21: Venmo/ATM | I21: -899.16
C22: ='Budget 26-27'!C22 -> Subscriptions | E22: ='Budget 26-27'!E22 -> 36.063333 | F22: ='Budget 26-27'!F22 -> 9.0158333 | H22: Billed Direct to Checking | I22: 90
C23: ='Budget 26-27'!C23 -> Total Fixed | E23: ='Budget 26-27'!E23 -> 1364.0633 | F23: ='Budget 26-27'!F23 -> 341.01583 | H23: Total Expenses | I23: =SUM(I17:I22) -> 9725.15 | J23: =SUM(J18:J22) -> 0 | K23: =SUM(K18:K22) -> 0 | L23: =SUM(L18:L22) -> 0 | M23: =SUM(M18:M22) -> 0 | N23: =SUM(N18:N22) -> 0 | O23: =SUM(O18:O22) -> 0 | P23: =SUM(P18:P22) -> 0 | Q23: =SUM(Q18:Q22) -> 0 | ... U23: =SUM(U18:U22) -> 0
H24: Budget | I24: 1 | J24: ='Budget 26-27'!J17 -> 3411.9133 | K24: ='Budget 26-27'!K17 -> 4549.0633 | L24: ='Budget 26-27'!L17 -> 4549.0633 | M24: ='Budget 26-27'!M17 -> 4549.0633 | N24: ='Budget 26-27'!N17 -> 4549.0633 | O24: ='Budget 26-27'!O17 -> 4549.0633 | P24: ='Budget 26-27'!P17 -> 4549.0633 | Q24: ='Budget 26-27'!Q17 -> 4549.0633 | ... U24: ='Budget 26-27'!U17 -> 4549.0633
C25: ='Budget 26-27'!C25 -> Discretionary Expenses | E25: ='Budget 26-27'!E25 -> 750 | F25: ='Budget 26-27'!F25 -> 187.5 | H25: % of Budget | I25: =I23/I24 -> 9725.15 | J25: =J23/J24 -> 0 | K25: =K23/K24 -> 0 | L25: =L23/L24 -> 0 | M25: =M23/M24 -> 0 | N25: =N23/N24 -> 0 | O25: =O23/O24 -> 0 | P25: =P23/P24 -> 0 | ... U25: =U23/U24 -> 0
H26: $ Saved/Over | I26: =IF(I23>0,I24-I23,"n.a.") -> -9724.15 | J26: =IF(J23>0,J24-J23,"n.a.") -> n.a. | K26: =IF(K23>0,K24-K23,"n.a.") -> n.a. | L26: =IF(L23>0,L24-L23,"n.a.") -> n.a. | M26: =IF(M23>0,M24-M23,"n.a.") -> n.a. | N26: =IF(N23>0,N24-N23,"n.a.") -> n.a. | O26: =IF(O23>0,O24-O23,"n.a.") -> n.a. | P26: =IF(P23>0,P24-P23,"n.a.") -> n.a. | ... U26: =IF(U23>0,U24-U23,"n.a.") -> n.a.
C27: ='Budget 26-27'!C27 -> Total Expenses | E27: ='Budget 26-27'!E27 -> 2114.0633 | F27: ='Budget 26-27'!F27 -> 528.51583
H28: Net Income | I28: =SUM(I11,-I23) -> -9725.15 | J28: =SUM(J11,-J23) -> 14333.667 | K28: =SUM(K11,-K23) -> 7333.6667 | L28: =SUM(L11,-L23) -> 7333.6667 | M28: =SUM(M11,-M23) -> 7333.6667 | N28: =SUM(N11,-N23) -> 7333.6667 | O28: =SUM(O11,-O23) -> 7333.6667 | P28: =SUM(P11,-P23) -> 7333.6667 | ... U28: =SUM(U11,-U23) -> 7333.6667
H29: % Saved | I29: =I28/I11 -> #DIV/0! | J29: =J28/J11 -> 1 | K29: =K28/K11 -> 1 | L29: =L28/L11 -> 1 | M29: =M28/M11 -> 1 | N29: =N28/N11 -> 1 | O29: =O28/O11 -> 1 | P29: =P28/P11 -> 1 | ... U29: =U28/U11 -> 1
C30: ='Budget 26-27'!C30 -> Rent | E30: ='Budget 26-27'!E30 -> Total | F30: ='Budget 26-27'!F30 -> Per Person
C31: ='Budget 26-27'!C31 -> First Month Cost: | E31: ='Budget 26-27'!E31 -> 24000 | F31: ='Budget 26-27'!F31 -> 8000 | H31: Pro Forma EOP Balance | I31: =H32+I28 -> #VALUE! | J31: =I32+J28 -> 14333.667 | K31: =J31+K28 -> 21667.333 | L31: =K31+L28 -> 29001 | M31: =L31+M28 -> 36334.667 | N31: =M31+N28 -> 43668.333 | O31: =N31+O28 -> 51002 | P31: =O31+P28 -> 58335.667 | Q31: =P31+Q28 -> 65669.333 | R31: =Q31+R28 -> 73003 | ... U31: =T31+U28 -> 95004
C32: ='Budget 26-27'!C32 -> Base Rent: | E32: ='Budget 26-27'!E32 -> 6950 | F32: ='Budget 26-27'!F32 -> 2316.6667 | H32: Actual EOP Balance
C33: ='Budget 26-27'!C33 -> ~Utilities: | E33: ='Budget 26-27'!E33 -> 355 | F33: ='Budget 26-27'!F33 -> 118.33333 | H33: % of budget | I33: =IFERROR(I32/'Budget 26-27'!J21,"n.a") -> 0 | J33: =IFERROR(J32/'Budget 26-27'!K21,"n.a") -> 0 | K33: =IFERROR(K32/'Budget 26-27'!L21,"n.a") -> 0 | L33: =IFERROR(L32/'Budget 26-27'!M21,"n.a") -> 0 | M33: =IFERROR(M32/'Budget 26-27'!N21,"n.a") -> 0 | N33: =IFERROR(N32/'Budget 26-27'!O21,"n.a") -> 0 | O33: =IFERROR(O32/'Budget 26-27'!P21,"n.a") -> 0 | P33: =IFERROR(P32/'Budget 26-27'!Q21,"n.a") -> 0 | ... U33: =IFERROR(U32/'Budget 26-27'!V21,"n.a") -> n.a
C36: ='Budget 26-27'!C36 -> Total Rent Monthly - First Month: | E36: ='Budget 26-27'!E36 -> 7305 | F36: ='Budget 26-27'!F36 -> 2435
C37: ='Budget 26-27'!C37 -> Total Rent Yearly: | E37: ='Budget 26-27'!E37 -> 104355 | F37: ='Budget 26-27'!F37 -> 34785 | I37: 1
H38: Weekly | I38: 2
C39: ='Budget 26-27'!H30 -> Subscriptions | D39: ='Budget 26-27'!I30 -> Per Month | I39: 3
C40: ='Budget 26-27'!H31 -> Apple Music | D40: ='Budget 26-27'!I31 -> 5.99 | I40: 4
C41: ='Budget 26-27'!H32 -> ICloud+ | D41: ='Budget 26-27'!I32 -> 2.99 | J41: =SUM(J37:J40) -> 0 | K41: =SUM(K37:K40) -> 0 | L41: =SUM(L37:L40) -> 0 | M41: =SUM(M37:M40) -> 0 | N41: =SUM(N37:N40) -> 0 | O41: =SUM(O37:O40) -> 0 | P41: =SUM(P37:P40) -> 0 | Q41: =SUM(Q37:Q40) -> 0 | ... U41: =SUM(U37:U40) -> 0
C42: ='Budget 26-27'!H33 -> AMEX Gold | D42: ='Budget 26-27'!I33 -> 27.083333 | I42: Budget/month | J42: =J43*4 -> 0 | K42: =K43*4 -> 0 | L42: =L43*4 -> 0 | M42: =M43*4 -> 0
I43: Budget/week | J43: =J22/4 -> 0 | K43: =K22/4 -> 0 | L43: =L22/4 -> 0 | M43: =M22/4 -> 0 | N43: =N22/4 -> 0 | O43: =O22/4 -> 0 | P43: =P22/4 -> 0 | Q43: =Q22/4 -> 0 | ... U43: =U22/4 -> 0
C46: ='Budget 26-27'!H37 -> Total: | D46: ='Budget 26-27'!I37 -> 36.063333
C48: ='Budget 26-27'!H23 -> LIRR Ticket Calc | E48: ='Budget 26-27'!J23 -> Per Month | F48: ='Budget 26-27'!K23 -> Per Week
...

Sheet 455 West 37th Street
B2: West 37th Breakdown
B3: Occupants: 3 | Amenities: Roof Deck, Lounges, Laundry
B5: Monthly Expense | C5: Total Cost | D5: Per Person | E5: Notes
B6: Rent | C6: 6950 | D6: =C6/3 + 50 -> 2366.6667
B7: Internet | C7: 75 | D7: =C7/3 -> 25 | E7: approximate
B8: Electric | C8: 140 | D8: =C8/3 -> 46.666667 | E8: approximate
B10: Total Monthly | C10: =SUM(C6:C9) -> 7165 | D10: =SUM(D6:D9) -> 2438.3333
B12: One-Time / Annual Fee | C12: Total Cost | D12: Per Person | E12: Notes
B13: Flex Wall Installation | C13: =1275+250 -> 1525 | D13: =C13/3 -> 508.33333
B14: Application Fee | C14: 20 | D14: =C14/3 -> 6.6666667
B15: Security Deposit | C15: 6950 | D15: =C15/3 -> 2316.6667
B16: Brokerage Fee | C16: 8340 | D16: =C16/3 -> 2780
B17: Total One-Time | C17: =SUM(C13:C16) -> 16835 | D17: =SUM(D13:D16) -> 5611.6667
B19: Total Estimated Move-In (First Month + Fees) | C19: =C10+C17 -> 24000 | D19: =D10+D17 -> 8050
B20: Total Yearly Cost: | C20: =C19 + (C10*11) -> 102815 | D20: =D19 + (D10*11) -> 34871.667

Sheet 455 West 37th Rent
B2: Costs | C2: July | D2: August | E2: September | F2: October | G2: November | H2: December | I2: January | J2: February | K2: March | L2: April | M2: May | N2: June
B3: Rent: | C3: 8050
B4: Power:
B5: Wifi:
B8: Grand Total: | C8: =SUM(C3:N3)+ SUM(C4:N4)+ SUM(C5:N5) + SUM(C6:N6) + F14 -> 8050
B14: Utilities: | C14: =SUM(C4:N6) -> 0
B17: Monthly | C17: Per Person | D17: Total
B18: Water | C18: =D18 / 6 -> 27.406667 | D18: 164.44
B19: Power | C19: =D19 / 6 -> 53.206667 | D19: 319.24
B20: Wifi | C20: =D20 / 6 -> 11.726667 | D20: 70.36
B21: Total | C21: =SUM(C18:C20) -> 92.34 | D21: =SUM(D18:D20) -> 554.04
B23: Compared to last month | C23: %∆ | D23: Last month
B24: Water | C24: =(C18 - D24) / D24 -> -0.079695545 | D24: 29.78
B25: Power | C25: =(C19 - D25) / D25 -> -0.35105907 | D25: 81.99
B26: Wifi | C26: =(C20 - D26) / D26 -> -0.00028417164 | D26: 11.73
B27: Total | C27: =(C21 - D27) / D27 -> -0.25224715 | D27: 123.49

Sheet Actual
C3: =TODAY() -> 46252 | D3: ACTUAL
C5: ='Budget 26-27'!C5 -> Income | E5: Gross | F5: Net | J5: ='Budget 26-27'!K5 -> 46295 | K5: ='Budget 26-27'!L5 -> 46325 | L5: ='Budget 26-27'!M5 -> 46356 | M5: ='Budget 26-27'!N5 -> 46386 | N5: ='Budget 26-27'!O5 -> 46417 | O5: ='Budget 26-27'!P5 -> 46446 | P5: ='Budget 26-27'!Q5 -> 46474 | Q5: ='Budget 26-27'!R5 -> 46505 | ... Y5: ='Budget 26-27'!Z5 -> 0
C6: ='Budget 26-27'!C6 -> Base Salary | E6: ='Budget 26-27'!E6 -> 122500 | F6: ='Budget 26-27'!F6 -> 88004 | H6: Income
C7: ='Budget 26-27'!C7 -> Tax Rate (State, Federal, City, Medicare, Social Security) | D7: ='Budget 26-27'!D7 -> 0.2816 | F7: ='Budget 26-27'!F7 -> 34496 | H7: Net Base Salary | J7: 3583.08 | K7: =3319.82+3311.46 -> 6631.28 | L7: =3364.73+3314.73 -> 6679.46 | M7: =(12636.14-9000)+3364.71 -> 7000.85 | N7: ='Budget 26-27'!O7 -> 7333.6667 | O7: ='Budget 26-27'!P7 -> 7333.6667 | P7: ='Budget 26-27'!Q7 -> 7333.6667 | Q7: ='Budget 26-27'!R7 -> 7333.6667 | R7: ='Budget 26-27'!S7 -> 7333.6667 | S7: ='Budget 26-27'!T7 -> 7333.6667 | T7: ='Budget 26-27'!U7 -> 7333.6667 | U7: ='Budget 26-27'!V7 -> 0 | ... Y7: ='Budget 26-27'!Z7 -> 0
C8: ='Budget 26-27'!C8 -> Per Month | E8: ='Budget 26-27'!E8 -> 10208.333 | F8: ='Budget 26-27'!F8 -> 7333.6667 | H8: Net Bonus | M8: =9000+600 -> 9600 | Y8: 38500
C9: ='Budget 26-27'!C9 -> Max Rent Pmt. | D9: ='Budget 26-27'!D9 -> 0.3 | E9: ='Budget 26-27'!E9 -> 3062.5 | F9: ='Budget 26-27'!F9 -> 2200.1 | H9: Investment
C10: ='Budget 26-27'!C10 -> Bonus Amount | E10: ='Budget 26-27'!E10 -> 10000 | F10: ='Budget 26-27'!F10 -> 7000 | H10: Tax Refund | K10: 200
C11: ='Budget 26-27'!C11 -> Tax Rate (State, Federal, City, Medicare, Social Security) | D11: ='Budget 26-27'!D11 -> 0.3 | F11: ='Budget 26-27'!F11 -> 3000 | H11: Total Income | J11: =SUM(J7:J10) -> 3583.08 | K11: =SUM(K7:K10) -> 6831.28 | L11: =SUM(L7:L10) -> 6679.46 | M11: =SUM(M7:M10) -> 16600.85 | N11: =SUM(N7:N10) -> 7333.6667 | O11: =SUM(O7:O10) -> 7333.6667 | P11: =SUM(P7:P10) -> 7333.6667 | Q11: =SUM(Q7:Q10) -> 7333.6667 | ... Y11: =SUM(Y7:Y10) -> 38500
C12: ='Budget 26-27'!C12 -> Bonus Payout Date | F12: ='Budget 26-27'!F12 -> 46235 | H12: Budget | J12: ='Budget 26-27'!K11 -> 7333.6667 | K12: ='Budget 26-27'!L11 -> 7333.6667 | L12: ='Budget 26-27'!M11 -> 7333.6667 | M12: ='Budget 26-27'!N11 -> 7333.6667 | N12: ='Budget 26-27'!O11 -> 7333.6667 | O12: ='Budget 26-27'!P11 -> 7333.6667 | P12: ='Budget 26-27'!Q11 -> 7333.6667 | Q12: ='Budget 26-27'!R11 -> 7333.6667 | ... Y12: ='Budget 26-27'!Z11 -> 0
C13: ='Budget 26-27'!C13 -> Total Salary | E13: ='Budget 26-27'!E13 -> 132500 | F13: ='Budget 26-27'!F13 -> 95004 | H13: % of Budget | J13: =J11/J12 -> 0.48857961 | K13: =K11/K12 -> 0.93149584 | L13: =L11/L12 -> 0.91079405 | M13: =M11/M12 -> 2.2636494 | N13: =N11/N12 -> 1 | O13: =O11/O12 -> 1 | P13: =P11/P12 -> 1 | Q13: =Q11/Q12 -> 1 | ... Y13: =Y11/Y12 -> #DIV/0!
C14: ='Budget 26-27'!C14 -> Total Tax | F14: ='Budget 26-27'!F14 -> 37496 | H14: $ Over/Under | J14: =J12-J11 -> 3750.5867 | K14: =K12-K11 -> 502.38667 | L14: =L12-L11 -> 654.20667 | M14: =M12-M11 -> -9267.1833 | N14: =N12-N11 -> 0 | O14: =O12-O11 -> 0 | P14: =P12-P11 -> 0 | Q14: =Q12-Q11 -> 0 | ... Y14: =Y12-Y11 -> -38500
C15: ='Budget 26-27'!C15 -> High Yield Savings APR | F15: ='Budget 26-27'!F15 -> 0
H16: Expense | AE16: =900*24 -> 21600
C17: ='Budget 26-27'!C17 -> Expenses | E17: ='Budget 26-27'!E17 -> Per Month | F17: ='Budget 26-27'!F17 -> Per Week | H17: Amex Blue | J17: 956.14 | K17: 976.34 | L17: 430.45 | M17: 444.55 | N17: 1700 | O17: 2200 | P17: 2000 | Q17: 2000 | R17: 2000 | S17: 2000 | T17: 2000 | U17: 1800 | V17: 1800 | W17: 1800 | X17: 1800 | Y17: 1800
C18: ='Budget 26-27'!C18 -> LIRR/Subway | E18: ='Budget 26-27'!E18 -> 60 | F18: ='Budget 26-27'!F18 -> 15 | H18: Amex Platinum | K18: =1645.08 -> 1645.08 | L18: 811.33 | M18: 2112.45 | U18: 2600 | V18: 2600 | W18: 2600 | X18: 2600 | Y18: 2600
C19: ='Budget 26-27'!C19 -> Lunch in Office | D19: ='Budget 26-27'!D19 -> 3 | E19: ='Budget 26-27'!E19 -> 168 | F19: ='Budget 26-27'!F19 -> 42 | H19: Chase | J19: 70.47 | K19: 36.73 | L19: 46.73 | M19: 36.73 | U19: 2000 | Y19: 3500
C20: ='Budget 26-27'!C20 -> Sunday Grocery | E20: ='Budget 26-27'!E20 -> 600 | F20: ='Budget 26-27'!F20 -> 150 | H20: Venmo/ATM | J20: =35+45 -> 80 | K20: 20 | L20: =7+170+45+200 -> 422 | M20: =456+13+44.5+50+20 -> 583.5 | Y20: 3500
C21: ='Budget 26-27'!C21 -> Jordan Travel | E21: ='Budget 26-27'!E21 -> 500 | F21: ='Budget 26-27'!F21 -> 125 | H21: Billed Direct to Checking | J21: =10.87+43.49 -> 54.36 | K21: =10.87+43.49 -> 54.36 | L21: =10.87+43.49 -> 54.36 | M21: =10.87+43.49 -> 54.36
C22: ='Budget 26-27'!C22 -> Subscriptions | E22: ='Budget 26-27'!E22 -> 36.063333 | F22: ='Budget 26-27'!F22 -> 9.0158333 | H22: Total Expenses | J22: =SUM(J17:J21) -> 1160.97 | K22: =SUM(K17:K21) -> 2732.51 | L22: =SUM(L17:L21) -> 1764.87 | M22: =SUM(M17:M21) -> 3231.59 | N22: =SUM(N17:N21) -> 1700 | O22: =SUM(O17:O21) -> 2200 | P22: =SUM(P17:P21) -> 2000 | Q22: =SUM(Q17:Q21) -> 2000 | ... Y22: =SUM(Y17:Y21) -> 11400
C23: ='Budget 26-27'!C23 -> Total Fixed | E23: ='Budget 26-27'!E23 -> 1364.0633 | F23: ='Budget 26-27'!F23 -> 341.01583 | H23: Budget | J23: ='Budget 26-27'!K17 -> 4549.0633 | K23: ='Budget 26-27'!L17 -> 4549.0633 | L23: ='Budget 26-27'!M17 -> 4549.0633 | M23: ='Budget 26-27'!N17 -> 4549.0633 | N23: ='Budget 26-27'!O17 -> 4549.0633 | O23: ='Budget 26-27'!P17 -> 4549.0633 | P23: ='Budget 26-27'!Q17 -> 4549.0633 | Q23: ='Budget 26-27'!R17 -> 4549.0633 | ... Y23: ='Budget 26-27'!Z17 -> 0
H24: % of Budget | J24: =J22/J23 -> 0.25521078 | K24: =K22/K23 -> 0.6006753 | L24: =L22/L23 -> 0.38796338 | M24: =M22/M23 -> 0.7103858 | N24: =N22/N23 -> 0.3737033 | O24: =O22/O23 -> 0.48361604 | P24: =P22/P23 -> 0.43965095 | Q24: =Q22/Q23 -> 0.43965095 | ... Y24: =Y22/Y23 -> #DIV/0!
C25: ='Budget 26-27'!C25 -> Discretionary Expenses | E25: ='Budget 26-27'!E25 -> 750 | F25: ='Budget 26-27'!F25 -> 187.5 | H25: $ Saved/Over | J25: =IF(J22>0,J23-J22,"n.a.") -> 3388.0933 | K25: =IF(K22>0,K23-K22,"n.a.") -> 1816.5533 | L25: =IF(L22>0,L23-L22,"n.a.") -> 2784.1933 | M25: =IF(M22>0,M23-M22,"n.a.") -> 1317.4733 | N25: =IF(N22>0,N23-N22,"n.a.") -> 2849.0633 | O25: =IF(O22>0,O23-O22,"n.a.") -> 2349.0633 | P25: =IF(P22>0,P23-P22,"n.a.") -> 2549.0633 | Q25: =IF(Q22>0,Q23-Q22,"n.a.") -> 2549.0633 | ... Y25: =IF(Y22>0,Y23-Y22,"n.a.") -> -11400
C27: ='Budget 26-27'!C27 -> Total Expenses | E27: ='Budget 26-27'!E27 -> 2114.0633 | F27: ='Budget 26-27'!F27 -> 528.51583 | H27: Net Income | J27: =SUM(J11,-J22) -> 2422.11 | K27: =SUM(K11,-K22) -> 4098.77 | L27: =SUM(L11,-L22) -> 4914.59 | M27: =SUM(M11,-M22) -> 13369.26 | N27: =SUM(N11,-N22) -> 5633.6667 | O27: =SUM(O11,-O22) -> 5133.6667 | P27: =SUM(P11,-P22) -> 5333.6667 | Q27: =SUM(Q11,-Q22) -> 5333.6667 | ... Y27: =SUM(Y11,-Y22) -> 27100
H28: % Saved | J28: =J27/J11 -> 0.67598547 | K28: =K27/K11 -> 0.60000029 | L28: =L27/L11 -> 0.73577654 | M28: =M27/M11 -> 0.80533587 | N28: =N27/N11 -> 0.76819235 | O28: =O27/O11 -> 0.70001364 | P28: =P27/P11 -> 0.72728512 | Q28: =Q27/Q11 -> 0.72728512 | ... Y28: =Y27/Y11 -> 0.7038961
C29: ='Budget 26-27'!H23 -> LIRR Ticket Calc | E29: ='Budget 26-27'!J23 -> Per Month | F29: ='Budget 26-27'!K23 -> Per Week
C30: ='Budget 26-27'!H24 -> Trips | E30: ='Budget 26-27'!J24 -> 32 | F30: ='Budget 26-27'!K24 -> 8 | H30: Pro Forma EOP Balance | J30: =I31+J27 -> 2705.86 | K30: =J31+K27 -> 6884.6 | L30: =K30+L27 -> 11799.19 | M30: =L30+M27 -> 25168.45 | N30: =M30+N27 -> 30802.117 | O30: =N30+O27 -> 35935.783 | P30: =O30+P27 -> 41269.45 | Q30: =P30+Q27 -> 46603.117 | R30: =Q30+R27 -> 51936.783 | S30: =R30+S27 -> 57270.45 | ... Y30: =X30+Y27 -> 70104.117
H31: Actual EOP Balance | I31: 283.75 | J31: =3866.83-1161+80 -> 2785.83 | K31: =9655.89-2733.51+20 -> 6942.38 | L31: 11857 | M31: =27899.76-3232+584 -> 25251.76 | AA31: *Checking account balance as of last day of month, less that months liabilities
C32: ='Budget 26-27'!H26 -> One Way Peak | D32: ='Budget 26-27'!I26 -> 17.5 | E32: ='Budget 26-27'!J26 -> 560 | F32: ='Budget 26-27'!K26 -> 140 | H32: % of budget | J32: =IFERROR(J31/'Budget 26-27'!K21,"n.a") -> 0.20325095 | K32: =IFERROR(K31/'Budget 26-27'!L21,"n.a") -> 0.42098095 | L32: =IFERROR(L31/'Budget 26-27'!M21,"n.a") -> 0.61513118 | M32: =IFERROR(M31/'Budget 26-27'!N21,"n.a") -> 1.1446768 | N32: =IFERROR(N31/'Budget 26-27'!O21,"n.a") -> 0 | O32: =IFERROR(O31/'Budget 26-27'!P21,"n.a") -> 0 | P32: =IFERROR(P31/'Budget 26-27'!Q21,"n.a") -> 0 | Q32: =IFERROR(Q31/'Budget 26-27'!R21,"n.a") -> 0 | ... Y32: =IFERROR(Y31/'Budget 26-27'!Z21,"n.a") -> n.a
C33: ='Budget 26-27'!H27 -> Monthly | E33: ='Budget 26-27'!J27 -> 341 | F33: ='Budget 26-27'!K27 -> 85.25
F34: ='Budget 26-27'!K28 -> 10.65625 | H34: PF Savings (Dec-26): | J34: {=SUM(J11:Y11,-J22:Y22)} -> 69740.397
I37: 1 | L37: =430+85+64 -> 579 | N37: =191+42+7+21+7+7.5+45+13.3+85+125 -> 543.8
H38: Weekly | I38: 2 | L38: =345+85+6 -> 436 | N38: =200+85 -> 285
I39: 3 | L39: =200+35+35+50+85 -> 405 | N39: =350+85 -> 435
I40: 4 | L40: =85+100+40 -> 225 | N40: =300+85 -> 385
L41: =SUM(L37:L40) -> 1645 | M41: =SUM(M37:M40) -> 0 | N41: =SUM(N37:N40) -> 1648.8 | O41: =SUM(O37:O40) -> 0 | P41: =SUM(P37:P40) -> 0 | Q41: =SUM(Q37:Q40) -> 0 | R41: =SUM(R37:R40) -> 0 | S41: =SUM(S37:S40) -> 0 | ... Y41: =SUM(Y37:Y40) -> 0
I42: Budget/month | L42: =L43*4 -> 1764.87 | M42: =M43*4 -> 3231.59
I43: Budget/week | L43: =L22/4 -> 441.2175 | M43: =M22/4 -> 807.8975 | N43: =N22/4 -> 425 | O43: =O22/4 -> 550 | P43: =P22/4 -> 500 | Q43: =Q22/4 -> 500 | R43: =R22/4 -> 500 | S43: =S22/4 -> 500 | ... Y43: =Y22/4 -> 2850
